<?xml version="1.0" ?>
<sdf version="1.6">
    <model name='vereniki'>
        <enable_wind>true</enable_wind>

        <link name='platform_body'>
            <inertial>
                <pose>0 0 0 0 0 0</pose>
                <mass>425.4534</mass>
                <inertia>
                    <ixx>555.133</ixx>
                    <ixy>0</ixy>
                    <ixz>-2.118</ixz>
                    <iyy>1007.443</iyy>
                    <iyz>-1.291</iyz>
                    <izz>1488.504</izz>
                </inertia>
            </inertial>

            <visual name='platform_visual'>
                <pose>0.02 0 -0.67 0 0 0</pose>
                <geometry>
                    <mesh>
                        <uri>model://vereniki/meshes/Vereniki.obj</uri>
                    </mesh>
                </geometry>
                <material>
                    <diffuse>1 1 1 1</diffuse>
                </material>

            </visual>
            <collision name='platform_collision'>
                <pose>0 0 0 0 0 0</pose>
                <geometry>
                    <mesh>
                        <uri>model://vereniki/meshes/vereniki_scaled3.stl</uri>
                    </mesh>
                </geometry>
            </collision>
        </link>

        <link name="engine_linkA">
            <pose>2.76029 0 -0.2 0 0 0</pose>
            <visual name="visual">
                <geometry>
                    <mesh>
                        <uri>model://wam-v/meshes/engine.dae</uri>
                    </mesh>
                </geometry>
            </visual>
        </link>
        <joint name="engine_jointA" type="revolute">
            <parent>platform_body</parent>
            <child>engine_linkA</child>
            <axis>
                <xyz>0 0 1</xyz>
            </axis>
        </joint>

        <link name="propeller_linkA">
            <pose relative_to="propeller_jointA">0 0 0 0 0 0</pose>
            <visual name="visual">
                <geometry>
                    <mesh>
                        <uri>model://wam-v/meshes/propeller.dae</uri>
                    </mesh>
                </geometry>
            </visual>
        </link>
        <joint name="propeller_jointA" type="revolute">
            <pose relative_to="engine_linkA">-0.278156 0 -0.509371 0 0 0</pose>
            <parent>engine_linkA</parent>
            <child>propeller_linkA</child>
            <axis>
                <xyz>1 0 0</xyz>
                <dynamics>
                    <damping>0.01</damping>
                </dynamics>
                <limit>
                    <lower>-1e+16</lower>
                    <upper>1e+16</upper>
                </limit>
            </axis>
        </joint>


        <link name="engine_linkB">
            <pose>-1.38549 1.75 -0.2 0 0 0</pose>
            <visual name="visual">
                <geometry>
                    <mesh>
                        <uri>model://wam-v/meshes/engine.dae</uri>
                    </mesh>
                </geometry>
            </visual>
        </link>
        <joint name="engine_jointB" type="revolute">
            <parent>platform_body</parent>
            <child>engine_linkB</child>
            <axis>
                <xyz>0 0 1</xyz>
            </axis>
        </joint>

        <link name="propeller_linkB">
            <pose relative_to="propeller_jointB">0 0 0 0 0 0</pose>
            <visual name="visual">
                <geometry>
                    <mesh>
                        <uri>model://wam-v/meshes/propeller.dae</uri>
                    </mesh>
                </geometry>
            </visual>
        </link>
        <joint name="propeller_jointB" type="revolute">
            <pose relative_to="engine_linkB">-0.278156 0 -0.509371 0 0 0</pose>
            <parent>engine_linkB</parent>
            <child>propeller_linkB</child>
            <axis>
                <xyz>1 0 0</xyz>
                <dynamics>
                    <damping>0.01</damping>
                </dynamics>
                <limit>
                    <lower>-1e+16</lower>
                    <upper>1e+16</upper>
                </limit>
            </axis>
        </joint>


        <link name="engine_linkC">
            <pose>-1.38549 -1.75 -0.2 0 0 0</pose>
            <visual name="visual">
                <geometry>
                    <mesh>
                        <uri>model://wam-v/meshes/engine.dae</uri>
                    </mesh>
                </geometry>
            </visual>
        </link>
        <joint name="engine_jointC" type="revolute">
            <parent>platform_body</parent>
            <child>engine_linkC</child>
            <axis>
                <xyz>0 0 1</xyz>
            </axis>
        </joint>

        <link name="propeller_linkC">
            <pose relative_to="propeller_jointC">0 0 0 0 0 0</pose>
            <visual name="visual">
                <geometry>
                    <mesh>
                        <uri>model://wam-v/meshes/propeller.dae</uri>
                    </mesh>
                </geometry>
            </visual>
        </link>
        <joint name="propeller_jointC" type="revolute">
            <pose relative_to="engine_linkC">-0.278156 0 -0.509371 0 0 0</pose>
            <parent>engine_linkC</parent>
            <child>propeller_linkC</child>
            <axis>
                <xyz>1 0 0</xyz>
                <dynamics>
                    <damping>0.01</damping>
                </dynamics>
                <limit>
                    <lower>-1e+16</lower>
                    <upper>1e+16</upper>
                </limit>
            </axis>
        </joint>

        <!-- Thruster plugins -->

        <!-- gz topic -t /model/vereniki/joint/propeller_jointA/cmd_vel -m gz.msgs.Double -p 'data: 100'-->
        <plugin
                filename="gz-sim-thruster-system"
                name="gz::sim::systems::Thruster">
            <namespace>vereniki</namespace>
            <joint_name>propeller_jointA</joint_name>
            <fluid_density>1025</fluid_density>
            <propeller_diameter>0.48</propeller_diameter>
            <thrust_coefficient>0.01</thrust_coefficient>
            <use_angvel_cmd>True</use_angvel_cmd>
            <velocity_control>True</velocity_control>

            <max_thrust_cmd>2000.0</max_thrust_cmd>
            <min_thrust_cmd>-2000.0</min_thrust_cmd>
        </plugin>

        <plugin
                filename="gz-sim-thruster-system"
                name="gz::sim::systems::Thruster">
            <namespace>vereniki</namespace>
            <joint_name>propeller_jointB</joint_name>
            <fluid_density>1025</fluid_density>
            <propeller_diameter>0.48</propeller_diameter>
            <thrust_coefficient>0.01</thrust_coefficient>
            <use_angvel_cmd>True</use_angvel_cmd>
            <velocity_control>True</velocity_control>

            <max_thrust_cmd>2000.0</max_thrust_cmd>
            <min_thrust_cmd>-2000.0</min_thrust_cmd>
        </plugin>

        <plugin
                filename="gz-sim-thruster-system"
                name="gz::sim::systems::Thruster">
            <namespace>vereniki</namespace>
            <joint_name>propeller_jointC</joint_name>
            <fluid_density>1025</fluid_density>
            <propeller_diameter>0.48</propeller_diameter>
            <thrust_coefficient>0.01</thrust_coefficient>
            <use_angvel_cmd>True</use_angvel_cmd>
            <velocity_control>True</velocity_control>

            <max_thrust_cmd>2000.0</max_thrust_cmd>
            <min_thrust_cmd>-2000.0</min_thrust_cmd>
        </plugin>

        <plugin
                filename="gz-sim-joint-position-controller-system"
                name="gz::sim::systems::JointPositionController">
            <joint_name>engine_jointA</joint_name>
            <p_gain>1</p_gain>
            <use_velocity_commands>True</use_velocity_commands>
            <topic>/model/vereniki/joint/engine_jointA/cmd_steer</topic>
            <cmd_max>1</cmd_max>
        </plugin>

        <plugin
                filename="gz-sim-joint-position-controller-system"
                name="gz::sim::systems::JointPositionController">
            <joint_name>engine_jointB</joint_name>
            <p_gain>1</p_gain>
            <use_velocity_commands>True</use_velocity_commands>
            <topic>/model/vereniki/joint/engine_jointB/cmd_steer</topic>
            <cmd_max>1</cmd_max>
        </plugin>

        <plugin
                filename="gz-sim-joint-position-controller-system"
                name="gz::sim::systems::JointPositionController">
            <joint_name>engine_jointC</joint_name>
            <p_gain>1</p_gain>
            <use_velocity_commands>True</use_velocity_commands>
            <topic>/model/vereniki/joint/engine_jointC/cmd_steer</topic>
            <cmd_max>1</cmd_max>
        </plugin>

        <plugin filename="libgz-sim-odometry-publisher-system.so"
                name="gz::sim::systems::OdometryPublisher">
        </plugin>

        <plugin filename="gz-sim-joint-state-publisher-system"
                name="gz::sim::systems::JointStatePublisher">
            <update_rate>10</update_rate>
            <joint_name>engine_jointA</joint_name>
            <joint_name>engine_jointB</joint_name>
            <joint_name>engine_jointC</joint_name>
            <joint_name>propeller_jointA</joint_name>
            <joint_name>propeller_jointB</joint_name>
            <joint_name>propeller_jointC</joint_name>
        </plugin>

        <plugin filename="gz-sim-imu-system"
                name="gz::sim::systems::Imu">
        </plugin>

        <!-- Sensors -->
        <link name="imu_link">
            <sensor name="imu_sensor" type="imu">
                <pose>0 0 0 0 0 0</pose>
                <always_on>1</always_on>
                <update_rate>1000.0</update_rate>
                <topic>/model/vereniki/imu</topic>
            </sensor>
        </link>
        <joint name="imu_joint" type="revolute">
            <child>imu_link</child>
            <parent>platform_body</parent>
            <axis>
                <xyz>0 0 1</xyz>
                <limit>
                    <lower>0</lower>
                    <upper>0</upper>
                    <effort>0</effort>
                    <velocity>0</velocity>
                </limit>
                <dynamics>
                    <damping>1.0</damping>
                </dynamics>
            </axis>
        </joint>

        <!-- Hydrodynamics plugin -->
        <plugin
                filename="gz-waves1-hydrodynamics-system"
                name="gz::sim::systems::Hydrodynamics">

            <enable>vereniki::platform_body</enable>

            <hydrodynamics>
                <damping_on>1</damping_on>
                <viscous_drag_on>1</viscous_drag_on>
                <pressure_drag_on>1</pressure_drag_on>

                <!-- Linear and Angular Damping -->
                <cDampL1>1.0E-6</cDampL1>
                <cDampL2>1.0E-6</cDampL2>
                <cDampR1>1.0E-6</cDampR1>
                <cDampR2>1.0E-6</cDampR2>

                <!-- 'Pressure' Drag -->
                <cPDrag1>1.0E+2</cPDrag1>
                <cPDrag2>1.0E+2</cPDrag2>
                <fPDrag>0.4</fPDrag>
                <cSDrag1>1.0E+2</cSDrag1>
                <cSDrag2>1.0E+2</cSDrag2>
                <fSDrag>0.4</fSDrag>
                <vRDrag>1.0</vRDrag>
            </hydrodynamics>
        </plugin>

        <plugin filename="ModelStatePublisher" name="model_state_publisher::ModelStatePublisher">
            <link_name>platform_body</link_name>
        </plugin>
    </model>
</sdf>