<?xml version="1.0" ?>
<sdf version="1.6">
    <model name='vereniki'>
        <enable_wind>true</enable_wind>

        <link name='platform_body'>
            <inertial>
                <pose>0 0 0.2 0 0 0</pose>
                <mass>425.4534</mass>
                <inertia>
                    <ixx>468.845</ixx>
                    <ixy>0</ixy>
                    <ixz>0</ixz>
                    <iyy>854.233</iyy>
                    <iyz>-1.291</iyz>
                    <izz>1267.66</izz>
                </inertia>
            </inertial>

            <visual name='platform_visual'>
                <pose>0 0 0 0 0 0</pose>
                <geometry>
                    <mesh>
                        <uri>model://vereniki/meshes/vereniki_scaled.obj</uri>
                    </mesh>
                </geometry>
                <material>
                    <diffuse>0.1 0.1 0.2 1</diffuse>
                </material>

            </visual>
            <collision name='platform_collision'>
                <pose>0 0 0 0 0 0</pose>
                <geometry>
                    <mesh>
                        <uri>model://vereniki/meshes/vereniki_scaled2.stl</uri>
                    </mesh>
                </geometry>
            </collision>
        </link>

        <link name="engine_link">
            <pose>0 0 0 0 0 0</pose>
            <visual name="visual">
                <geometry>
                    <mesh>
                        <uri>model://wam-v/meshes/engine.dae</uri>
                    </mesh>
                </geometry>
            </visual>
            <collision name="engine_vertical_axis_collision">
                <pose>-0.16 0 -0.215 0 0 0</pose>
                <geometry>
                    <box>
                        <size>0.2 0.1 0.83</size>
                    </box>
                </geometry>
            </collision>
            <collision name="engine_rear_end_collision">
                <pose>-0.34 0 0.12 0 0 0</pose>
                <geometry>
                    <box>
                        <size>0.12 0.15 0.12</size>
                    </box>
                </geometry>
            </collision>
            <inertial>
                <mass>15</mass>
                <inertia>
                    <ixx>0.88924</ixx>
                    <ixy>0</ixy>
                    <iyy>0.911125</iyy>
                    <iyz>0</iyz>
                    <izz>0.078125</izz>
                </inertia>
            </inertial>
        </link>
        <joint name="engine_joint" type="revolute">
            <parent>platform_body</parent>
            <child>engine_link</child>
            <axis>
                <xyz>0 0 1</xyz>
                <limit>
                    <lower>-1.57</lower>
                    <upper>1.57</upper>
                    <stifness>10</stifness>
                </limit>
                <dynamics>
                    <damping>30</damping>
                    <spring_stiffness>100.0</spring_stiffness>
                    <spring_reference>0</spring_reference>
                    <friction>1.0</friction>
                </dynamics>
            </axis>
        </joint>

        <link name="propeller_link">
            <pose relative_to="propeller_joint">0 0 0 0 0 0</pose>
            <visual name="visual">
                <geometry>
                    <mesh>
                        <uri>model://wam-v/meshes/propeller.dae</uri>
                    </mesh>
                </geometry>
            </visual>
            <collision name="collision">
                <pose>-0.11 0 0 0 1.570796 0</pose>
                <geometry>
                    <cylinder>
                        <length>0.08</length>
                        <radius>0.24</radius>
                    </cylinder>
                </geometry>
            </collision>
            <inertial>
                <mass>0.5</mass>
                <inertia>
                    <ixx>0.008545</ixx>
                    <ixy>0</ixy>
                    <iyy>0.008545</iyy>
                    <iyz>0</iyz>
                    <izz>0.0144</izz>
                </inertia>
            </inertial>
        </link>
        <joint name="propeller_joint" type="revolute">
            <pose relative_to="engine_link">-0.278156 0 -0.509371 0 0 0</pose>
            <parent>engine_link</parent>
            <child>propeller_link</child>
            <axis>
                <xyz>1 0 0</xyz>
                <dynamics>
                    <damping>0.01</damping>
                </dynamics>
                <limit>
                    <lower>-1e+16</lower>
                    <upper>1e+16</upper>
                </limit>
            </axis>
        </joint>

        <!-- Thruster plugins -->
        <plugin
                filename="gz-sim-thruster-system"
                name="gz::sim::systems::Thruster">
            <namespace>vereniki</namespace>
            <joint_name>propeller_joint</joint_name>
            <fluid_density>1025</fluid_density>
            <propeller_diameter>0.48</propeller_diameter>
            <thrust_coefficient>0.01</thrust_coefficient>
            <p_gain>1</p_gain>

            <max_thrust_cmd>10000.0</max_thrust_cmd>
            <min_thrust_cmd>-10000.0</min_thrust_cmd>
        </plugin>


        <!-- Hydrodynamics plugin -->
        <plugin
                filename="gz-waves1-hydrodynamics-system"
                name="gz::sim::systems::Hydrodynamics">

            <enable>vereniki::platform_body</enable>

            <hydrodynamics>
                <damping_on>1</damping_on>
                <viscous_drag_on>1</viscous_drag_on>
                <pressure_drag_on>1</pressure_drag_on>

                <!-- Linear and Angular Damping -->
                <cDampL1>1.0E-6</cDampL1>
                <cDampL2>1.0E-6</cDampL2>
                <cDampR1>1.0E-6</cDampR1>
                <cDampR2>1.0E-6</cDampR2>

                <!-- 'Pressure' Drag -->
                <cPDrag1>1.0E+2</cPDrag1>
                <cPDrag2>1.0E+2</cPDrag2>
                <fPDrag>0.4</fPDrag>
                <cSDrag1>1.0E+2</cSDrag1>
                <cSDrag2>1.0E+2</cSDrag2>
                <fSDrag>0.4</fSDrag>
                <vRDrag>1.0</vRDrag>
            </hydrodynamics>
        </plugin>
    </model>
</sdf>