<?xml version="1.0" ?>
<sdf version="1.6">
    <model name='boat'>
        <enable_wind>true</enable_wind>

        <link name='boat_body'>
            <inertial>
                <pose>0.999251 0.000005 -1.223034 0 0 0</pose>
                <mass>1610</mass>
                <inertia>
                    <ixx>1.325642e+2</ixx>
                    <ixy>-0.000002e+2</ixy>
                    <ixz>0.121894e+2</ixz>
                    <iyy>4.792929e+2</iyy>
                    <iyz>0.000095e+2</iyz>
                    <izz>5.052444e+2</izz>
                </inertia>

<!--                | 1.325642 -0.000002 0.121894 |-->
<!--                | -0.000002 4.792929 0.000095 |-->
<!--                | 0.121894 0.000095 5.052444 |-->
            </inertial>

            <visual name='boat_visual'>
                <geometry>
                    <mesh>
                        <uri>model://boat/meshes/boat3.dae</uri>
                    </mesh>
                </geometry>
                <material>
                    <ambient>0.1 0.1 0.1 1</ambient>
                    <diffuse>0.1 0.1 0.2 1</diffuse>
                    <specular>0 0 0 0</specular>
                    <emissive>0 0 0 1</emissive>
                </material>
            </visual>
            <collision name='boat_collision'>
                <geometry>
                    <mesh>
                        <uri>model://boat/meshes/boat3.stl</uri>
                    </mesh>
                </geometry>
            </collision>

<!--            <sensor name="imu" type="imu">-->
<!--                <update_rate>30</update_rate>-->
<!--                <plugin filename="libgz-sim-imu-system.so"-->
<!--                        name="gz::sim::v7::systems::Imu">-->

<!--                </plugin>-->
<!--            </sensor>-->
        </link>

        <link name="engine_link">
            <pose>0 0 -1 0 0 0</pose>
            <visual name="visual">
                <geometry>
                    <mesh>
                        <uri>model://wam-v/meshes/engine.dae</uri>
                    </mesh>
                </geometry>
            </visual>
            <collision name="engine_vertical_axis_collision">
                <pose>-0.16 0 -0.215 0 0 0</pose>
                <geometry>
                    <box>
                        <size>0.2 0.1 0.83</size>
                    </box>
                </geometry>
            </collision>
            <collision name="engine_rear_end_collision">
                <pose>-0.34 0 0.12 0 0 0</pose>
                <geometry>
                    <box>
                        <size>0.12 0.15 0.12</size>
                    </box>
                </geometry>
            </collision>
            <inertial>
                <mass>15</mass>
                <inertia>
                    <ixx>0.88924</ixx>
                    <ixy>0</ixy>
                    <iyy>0.911125</iyy>
                    <iyz>0</iyz>
                    <izz>0.078125</izz>
                </inertia>
            </inertial>
        </link>
        <joint name="engine_joint" type="revolute">
            <parent>boat_body</parent>
            <child>engine_link</child>
            <axis>
                <xyz>0 0 1</xyz>
                <limit>
                    <lower>-1.57</lower>
                    <upper>1.57</upper>
                    <stifness>10</stifness>
                </limit>
                <dynamics>
                    <damping>30</damping>
                    <spring_stiffness>100.0</spring_stiffness>
                    <spring_reference>0</spring_reference>
                    <friction>1.0</friction>
                </dynamics>
            </axis>
        </joint>

        <link name="propeller_link">
            <pose relative_to="propeller_joint">0 0 0 0 0 0</pose>
            <visual name="visual">
                <geometry>
                    <mesh>
                        <uri>model://wam-v/meshes/propeller.dae</uri>
                    </mesh>
                </geometry>
            </visual>
            <collision name="collision">
                <pose>-0.11 0 0 0 1.570796 0</pose>
                <geometry>
                    <cylinder>
                        <length>0.08</length>
                        <radius>0.24</radius>
                    </cylinder>
                </geometry>
            </collision>
            <inertial>
                <mass>0.5</mass>
                <inertia>
                    <ixx>0.008545</ixx>
                    <ixy>0</ixy>
                    <iyy>0.008545</iyy>
                    <iyz>0</iyz>
                    <izz>0.0144</izz>
                </inertia>
            </inertial>
        </link>
        <joint name="propeller_joint" type="revolute">
            <pose relative_to="engine_link">-0.278156 0 -0.509371 0 0 0</pose>
            <parent>engine_link</parent>
            <child>propeller_link</child>
            <axis>
                <xyz>1 0 0</xyz>
                <dynamics>
                    <damping>0.01</damping>
                </dynamics>
                <limit>
                    <lower>-1e+16</lower>
                    <upper>1e+16</upper>
                </limit>
            </axis>
        </joint>

        <plugin filename="gz-sim-joint-state-publisher-system"
                name="gz::sim::systems::JointStatePublisher">
            <update_rate>30</update_rate>
            <joint_name>engine_joint</joint_name>
            <joint_name>propeller_joint</joint_name>
        </plugin>

        <plugin filename="libgz-sim-odometry-publisher-system.so"
                name="gz::sim::systems::OdometryPublisher">
        </plugin>

<!--
        1. Steer the engine:

        gz topic -t /model/boat/joint/engine_joint/cmd_steer \
        -m gz.msgs.Double -p 'data: -0.17'

        2. Propel the vehicle:

        + If use_angvel_cmd is 0:
          gz topic -t /model/boat/joint/propeller_joint/cmd_thrust
          -m gz.msgs.Double -p 'data: 1625'
        + else
          gz topic -t /model/boat/joint/propeller_joint/cmd_vel
          -m gz.msgs.Double -p 'data: 55'
-->

        <plugin
                filename="gz-sim-joint-position-controller-system"
                name="gz::sim::systems::JointPositionController">
            <joint_name>engine_joint</joint_name>
            <p_gain>1</p_gain>
<!--            <i_gain>0.1</i_gain>-->
<!--            <d_gain>0.01</d_gain>-->
<!--            <i_max>1</i_max>-->
<!--            <i_min>-1</i_min>-->
<!--            <p_gain>0.05</p_gain>-->
<!--            <cmd_max>1000</cmd_max>-->
<!--            <cmd_min>-1000</cmd_min>-->
            <topic>/model/boat/joint/engine_joint/cmd_steer</topic>
        </plugin>

        <!-- Thruster plugins -->
        <plugin
                filename="gz-sim-thruster-system"
                name="gz::sim::systems::Thruster">
            <namespace>boat</namespace>
            <joint_name>propeller_joint</joint_name>
<!--            <use_angvel_cmd>1</use_angvel_cmd>-->
            <fluid_density>1025</fluid_density>
            <propeller_diameter>0.48</propeller_diameter>
            <thrust_coefficient>0.01</thrust_coefficient>
            <p_gain>1</p_gain>

            <max_thrust_cmd>10000.0</max_thrust_cmd>
            <min_thrust_cmd>-10000.0</min_thrust_cmd>
        </plugin>


        <!-- Hydrodynamics plugin -->
        <plugin
                filename="gz-waves1-hydrodynamics-system"
                name="gz::sim::systems::Hydrodynamics">

            <enable>boat::boat_body</enable>

            <hydrodynamics>
                <damping_on>1</damping_on>
                <viscous_drag_on>1</viscous_drag_on>
                <pressure_drag_on>1</pressure_drag_on>

                <!-- Linear and Angular Damping -->
                <cDampL1>1.0E-6</cDampL1>
                <cDampL2>1.0E-6</cDampL2>
                <cDampR1>1.0E-6</cDampR1>
                <cDampR2>1.0E-6</cDampR2>

                <!-- 'Pressure' Drag -->
                <cPDrag1>1.0E+2</cPDrag1>
                <cPDrag2>1.0E+2</cPDrag2>
                <fPDrag>0.4</fPDrag>
                <cSDrag1>1.0E+2</cSDrag1>
                <cSDrag2>1.0E+2</cSDrag2>
                <fSDrag>0.4</fSDrag>
                <vRDrag>1.0</vRDrag>
            </hydrodynamics>
        </plugin>
    </model>
</sdf>